<?xml version="1.0" encoding="utf-8"?>
<!-- This URDF was automatically created by SolidWorks to URDF Exporter! Originally created by Stephen Brawner (brawner@gmail.com) 
     Commit Version: 1.5.1-0-g916b5db  Build Version: 1.5.7152.31018
     For more information, please see http://wiki.ros.org/sw_urdf_exporter -->
<robot
  name="artpark">
  <link
    name="base_link">
    <inertial>
      <origin
        xyz="0.0054181 3.1494E-05 0.074438"
        rpy="0 0 0" />
      <mass
        value="3.6566" />
      <inertia
        ixx="0.093914"
        ixy="8.6818E-06"
        ixz="-0.0082304"
        iyy="0.090755"
        iyz="3.4188E-06"
        izz="0.13406" />
    </inertial>
    <visual>
      <origin
        xyz="0 0 0"
        rpy="0 0 0" />
      <geometry>
        <mesh
          filename="package://artpark/meshes/base_link.STL" />
      </geometry>
      <material
        name="">
        <color
          rgba="0.89804 0.91765 0.92941 1" />
      </material>
    </visual>
    <collision>
      <origin
        xyz="0 0 0"
        rpy="0 0 0" />
      <geometry>
        <mesh
          filename="package://artpark/meshes/base_link.STL" />
      </geometry>
    </collision>
  </link>
  <link
    name="chassis">
    <inertial>
      <origin
        xyz="0.0054181 3.1494E-05 0.074438"
        rpy="0 0 0" />
      <mass
        value="3.6566" />
      <inertia
        ixx="0.093914"
        ixy="8.6818E-06"
        ixz="-0.0082304"
        iyy="0.090755"
        iyz="3.4188E-06"
        izz="0.13406" />
    </inertial>
    <visual>
      <origin
        xyz="0 0 0"
        rpy="0 0 0" />
      <geometry>
        <mesh
          filename="package://artpark/meshes/chassis.STL" />
      </geometry>
      <material
        name="">
        <color
          rgba="0.89804 0.91765 0.92941 1" />
      </material>
    </visual>
    <collision>
      <origin
        xyz="0 0 0"
        rpy="0 0 0" />
      <geometry>
        <mesh
          filename="package://artpark/meshes/chassis.STL" />
      </geometry>
    </collision>
  </link>
  <joint
    name="base"
    type="fixed">
    <origin
      xyz="0 0 0"
      rpy="0 0 0" />
    <parent
      link="base_link" />
    <child
      link="chassis" />
    <axis
      xyz="0 0 0" />
  </joint>
  <link
    name="side_plate1">
    <inertial>
      <origin
        xyz="8.3267E-17 -0.0015 -8.3267E-17"
        rpy="0 0 0" />
      <mass
        value="0.8912" />
      <inertia
        ixx="0.0055992"
        ixy="-9.938E-17"
        ixz="0.0011538"
        iyy="0.018787"
        iyz="4.2411E-17"
        izz="0.013189" />
    </inertial>
    <visual>
      <origin
        xyz="0 0 0"
        rpy="0 0 0" />
      <geometry>
        <mesh
          filename="package://artpark/meshes/side_plate1.STL" />
      </geometry>
      <material
        name="">
        <color
          rgba="0.89804 0.91765 0.92941 1" />
      </material>
    </visual>
    <collision>
      <origin
        xyz="0 0 0"
        rpy="0 0 0" />
      <geometry>
        <mesh
          filename="package://artpark/meshes/side_plate1.STL" />
      </geometry>
    </collision>
  </link>
  <joint
    name="sp1"
    type="fixed">
    <origin
      xyz="-0.27395 0.213 0.09851"
      rpy="0 0 0" />
    <parent
      link="chassis" />
    <child
      link="side_plate1" />
    <axis
      xyz="0 0 0" />
  </joint>
  <link
    name="picker">
    <inertial>
      <origin
        xyz="-0.0081479 0.003007 -0.030744"
        rpy="0 0 0" />
      <mass
        value="1.3054" />
      <inertia
        ixx="0.019919"
        ixy="2.7653E-05"
        ixz="-0.00040516"
        iyy="0.0018485"
        iyz="0.00010428"
        izz="0.018506" />
    </inertial>
    <visual>
      <origin
        xyz="0 0 0"
        rpy="0 0 0" />
      <geometry>
        <mesh
          filename="package://artpark/meshes/picker.STL" />
      </geometry>
      <material
        name="">
        <color
          rgba="1 1 1 1" />
      </material>
    </visual>
    <collision>
      <origin
        xyz="0 0 0"
        rpy="0 0 0" />
      <geometry>
        <mesh
          filename="package://artpark/meshes/picker.STL" />
      </geometry>
    </collision>
  </link>
  <joint
    name="pic"
    type="continuous">
    <origin
      xyz="-0.015668 -0.21352 -0.027594"
      rpy="0 0 0" />
    <parent
      link="side_plate1" />
    <child
      link="picker" />
    <axis
      xyz="0 -1 0" />
    <transmission name="pic_trans">
    <type>transmission_interface/SimpleTransmission</type>
    <joint name="pic">
      <hardwareInterface>hardware_interface/EffortJointInterface</hardwareInterface>
    </joint>
    <actuator name="pic_motor"></actuator>
  </transmission>
  </joint>
  <link
    name="side_plate2">
    <inertial>
      <origin
        xyz="-8.3267E-17 0.0015 2.7756E-17"
        rpy="0 0 0" />
      <mass
        value="0.8912" />
      <inertia
        ixx="0.0055992"
        ixy="-7.0634E-18"
        ixz="0.0011538"
        iyy="0.018787"
        iyz="3.4177E-17"
        izz="0.013189" />
    </inertial>
    <visual>
      <origin
        xyz="0 0 0"
        rpy="0 0 0" />
      <geometry>
        <mesh
          filename="package://artpark/meshes/side_plate2.STL" />
      </geometry>
      <material
        name="">
        <color
          rgba="0.89804 0.91765 0.92941 1" />
      </material>
    </visual>
    <collision>
      <origin
        xyz="0 0 0"
        rpy="0 0 0" />
      <geometry>
        <mesh
          filename="package://artpark/meshes/side_plate2.STL" />
      </geometry>
    </collision>
  </link>
  <joint
    name="sp2"
    type="fixed">
    <origin
      xyz="-0.27395 -0.213 0.09851"
      rpy="0 0 0" />
    <parent
      link="chassis" />
    <child
      link="side_plate2" />
    <axis
      xyz="0 0 0" />
  </joint>
  <link
    name="motor1">
    <inertial>
      <origin
        xyz="0 -0.080765 -4.8572E-16"
        rpy="0 0 0" />
      <mass
        value="1.1451" />
      <inertia
        ixx="0.0016251"
        ixy="2.1834E-20"
        ixz="-1.5767E-21"
        iyy="0.00025812"
        iyz="-8.3292E-18"
        izz="0.0016251" />
    </inertial>
    <visual>
      <origin
        xyz="0 0 0"
        rpy="0 0 0" />
      <geometry>
        <mesh
          filename="package://artpark/meshes/motor1.STL" />
      </geometry>
      <material
        name="">
        <color
          rgba="0.83137 0.83922 0.83137 1" />
      </material>
    </visual>
    <collision>
      <origin
        xyz="0 0 0"
        rpy="0 0 0" />
      <geometry>
        <mesh
          filename="package://artpark/meshes/motor1.STL" />
      </geometry>
    </collision>
  </link>
  <joint
    name="m1"
    type="fixed">
    <origin
      xyz="-0.11085 0.176 0.038"
      rpy="0 0 0" />
    <parent
      link="chassis" />
    <child
      link="motor1" />
    <axis
      xyz="0 0 0" />
  </joint>
  <link
    name="wheel1">
    <inertial>
      <origin
        xyz="8.2573E-16 -0.0098577 -5.5511E-17"
        rpy="0 0 0" />
      <mass
        value="0.34943" />
      <inertia
        ixx="0.00052614"
        ixy="7.9115E-19"
        ixz="6.1497E-18"
        iyy="0.0010155"
        iyz="2.9998E-18"
        izz="0.00052614" />
    </inertial>
    <visual>
      <origin
        xyz="0 0 0"
        rpy="0 0 0" />
      <geometry>
        <mesh
          filename="package://artpark/meshes/wheel1.STL" />
      </geometry>
      <material
        name="">
        <color
          rgba="1 1 1 1" />
      </material>
    </visual>
    <collision>
      <origin
        xyz="0 0 0"
        rpy="0 0 0" />
      <geometry>
        <mesh
          filename="package://artpark/meshes/wheel1.STL" />
      </geometry>
    </collision>
  </link>
  <joint
    name="w1"
    type="continuous">
    <origin
      xyz="0 0.064701 0"
      rpy="0 0 0" />
    <parent
      link="motor1" />
    <child
      link="wheel1" />
    <axis
      xyz="0 -1 0" />
    <transmission name="W1_trans">
    <type>transmission_interface/SimpleTransmission</type>
    <joint name="w1">
      <hardwareInterface>hardware_interface/EffortJointInterface</hardwareInterface>
    </joint>
    <actuator name="W1_motor"></actuator>
  </transmission>
  </joint>
  <link
    name="motor2">
    <inertial>
      <origin
        xyz="-3.4694E-18 -0.028001 -1.5266E-16"
        rpy="0 0 0" />
      <mass
        value="1.1451" />
      <inertia
        ixx="0.0016251"
        ixy="5.8596E-20"
        ixz="7.5488E-21"
        iyy="0.00025812"
        iyz="-8.3678E-18"
        izz="0.0016251" />
    </inertial>
    <visual>
      <origin
        xyz="0 0 0"
        rpy="0 0 0" />
      <geometry>
        <mesh
          filename="package://artpark/meshes/motor2.STL" />
      </geometry>
      <material
        name="">
        <color
          rgba="0.83137 0.83922 0.83137 1" />
      </material>
    </visual>
    <collision>
      <origin
        xyz="0 0 0"
        rpy="0 0 0" />
      <geometry>
        <mesh
          filename="package://artpark/meshes/motor2.STL" />
      </geometry>
    </collision>
  </link>
  <joint
    name="m2"
    type="fixed">
    <origin
      xyz="-0.11085 -0.067234 0.038"
      rpy="0 0 0" />
    <parent
      link="chassis" />
    <child
      link="motor2" />
    <axis
      xyz="0 0 0" />
  </joint>
  <link
    name="wheel2">
    <inertial>
      <origin
        xyz="7.6675E-16 0.0098577 3.747E-16"
        rpy="0 0 0" />
      <mass
        value="0.34943" />
      <inertia
        ixx="0.00052614"
        ixy="-8.49E-19"
        ixz="4.1041E-17"
        iyy="0.0010155"
        iyz="2.6206E-18"
        izz="0.00052614" />
    </inertial>
    <visual>
      <origin
        xyz="0 0 0"
        rpy="0 0 0" />
      <geometry>
        <mesh
          filename="package://artpark/meshes/wheel2.STL" />
      </geometry>
      <material
        name="">
        <color
          rgba="1 1 1 1" />
      </material>
    </visual>
    <collision>
      <origin
        xyz="0 0 0"
        rpy="0 0 0" />
      <geometry>
        <mesh
          filename="package://artpark/meshes/wheel2.STL" />
      </geometry>
    </collision>
  </link>
  <joint
    name="w2"
    type="continuous">
    <origin
      xyz="0 -0.17347 0"
      rpy="0 0 0" />
    <parent
      link="motor2" />
    <child
      link="wheel2" />
    <axis
      xyz="0 1 0" />
    <transmission name="W2_trans">
    <type>transmission_interface/SimpleTransmission</type>
    <joint name="w2">
      <hardwareInterface>hardware_interface/EffortJointInterface</hardwareInterface>
    </joint>
    <actuator name="W2_motor"></actuator>
  </transmission>
  </joint>
  <link
    name="rplidar">
    <inertial>
      <origin
        xyz="0.0057842 0.00062655 -0.019562"
        rpy="0 0 0" />
      <mass
        value="0.14299" />
      <inertia
        ixx="4.6277E-05"
        ixy="-8.5349E-07"
        ixz="3.6217E-06"
        iyy="7.3474E-05"
        iyz="-2.0431E-07"
        izz="0.00010796" />
    </inertial>
    <visual>
      <origin
        xyz="0 0 0"
        rpy="0 0 0" />
      <geometry>
        <mesh
          filename="package://artpark/meshes/rplidar.STL" />
      </geometry>
      <material
        name="">
        <color
          rgba="0.79216 0.81961 0.93333 1" />
      </material>
    </visual>
    <collision>
      <origin
        xyz="0 0 0"
        rpy="0 0 0" />
      <geometry>
        <mesh
          filename="package://artpark/meshes/rplidar.STL" />
      </geometry>
    </collision>
  </link>
  <joint
    name="rpl1"
    type="fixed">
    <origin
      xyz="0.052154 -0.00013645 0.5646"
      rpy="0 0 0" />
    <parent
      link="chassis" />
    <child
      link="rplidar" />
    <axis
      xyz="0 0 0" />
  </joint>
  <link
    name="castor">
    <inertial>
      <origin
        xyz="4.8962E-07 -3.2749E-07 0.001332"
        rpy="0 0 0" />
      <mass
        value="0.0034759" />
      <inertia
        ixx="3.2924E-07"
        ixy="1.5654E-13"
        ixz="-7.4284E-12"
        iyy="3.2924E-07"
        iyz="3.4552E-12"
        izz="5.808E-07" />
    </inertial>
    <visual>
      <origin
        xyz="0 0 0"
        rpy="0 0 0" />
      <geometry>
        <mesh
          filename="package://artpark/meshes/castor.STL" />
      </geometry>
      <material
        name="">
        <color
          rgba="0.84314 0 0.15294 1" />
      </material>
    </visual>
    <collision>
      <origin
        xyz="0 0 0"
        rpy="0 0 0" />
      <geometry>
        <mesh
          filename="package://artpark/meshes/castor.STL" />
      </geometry>
    </collision>
  </link>
  <joint
    name="c1"
    type="fixed">
    <origin
      xyz="0.22915 0 -0.022236"
      rpy="0 0 0" />
    <parent
      link="chassis" />
    <child
      link="castor" />
    <axis
      xyz="0 0 0" />
  </joint>
  <link
    name="castor_ball">
    <inertial>
      <origin
        xyz="0 0 0"
        rpy="0 0 0" />
      <mass
        value="0.00065958" />
      <inertia
        ixx="7.6934E-09"
        ixy="2.7917E-25"
        ixz="2.2334E-25"
        iyy="7.6934E-09"
        iyz="-1.675E-25"
        izz="7.6934E-09" />
    </inertial>
    <visual>
      <origin
        xyz="0 0 0"
        rpy="0 0 0" />
      <geometry>
        <mesh
          filename="package://artpark/meshes/castor_ball.STL" />
      </geometry>
      <material
        name="">
        <color
          rgba="0.69804 0.69804 0.69804 1" />
      </material>
    </visual>
    <collision>
      <origin
        xyz="0 0 0"
        rpy="0 0 0" />
      <geometry>
        <mesh
          filename="package://artpark/meshes/castor_ball.STL" />
      </geometry>
    </collision>
  </link>
  <joint
    name="b1"
    type="continuous">
    <origin
      xyz="0 0 -0.0071933"
      rpy="0 0 0" />
    <parent
      link="castor" />
    <child
      link="castor_ball" />
    <axis
      xyz="0 1 0" />
  </joint>
</robot>