<?xml version="1.0" ?>
<!-- =================================================================================== -->
<!-- |    This document was autogenerated by xacro from artpark.urdf.xacro             | -->
<!-- |    EDITING THIS FILE BY HAND IS NOT RECOMMENDED                                 | -->
<!-- =================================================================================== -->
<robot name="artpark">
  <!-- T265 Fisheye:

  gazebo_ros_camera supports only plumb_bob
  D: [-0.007419134024530649, 0.041209351271390915, -0.03811917081475258, 0.006366158835589886, 0.0]

  <distortionK1>-0.007419134024530649</distortionK1>
  <distortionK2>0.041209351271390915</distortionK2>
  <distortionK3>-0.03811917081475258</distortionK3>
  <distortionT1>0.006366158835589886</distortionT1>
  <distortionT2>0.0</distortionT2>

       [fx'  0  cx' Tx]
   P = [ 0  fy' cy' Ty]
       [ 0   0   1   0]

   P : [ 285.5480041503906, 0.0, 416.00531005859375, 0.0,
         0.0, 285.3793029785156, 403.38909912109375, 0.0,
         0.0, 0.0, 1.0, 0.0 ]

  <CxPrime>416.00531005859375</CxPrime>

       [fx  0 cx]
   K = [ 0 fy cy]
       [ 0  0  1]

   K : [ 285.5480041503906, 0.0, 416.00531005859375,
         0.0, 285.3793029785156, 403.38909912109375,
         0.0, 0.0, 1.0]

  <Cx>16.00531005859375</Cx>
  <Cy>403.38909912109375</Cy>

  -->
  <!-- INTEL REALSENSE T265 -->
  <!-- INTEL REALSENSE D435 -->
  <!-- INTEL REALSENSE R200 -->
  <link name="base_link">
    <visual>
      <origin rpy="0 0 0" xyz="0 0 0"/>
    </visual>
    <collision>
      <origin rpy="0 0 0" xyz="0 0 0"/>
      <geometry>
        <mesh filename="package://artpark/meshes/base_link.STL"/>
      </geometry>
    </collision>
  </link>
  <link name="chassis">
    <inertial>
      <origin rpy="0 0 0" xyz="0.0115454940351985 -3.15080247147437E-05 0.0744738556693311"/>
      <mass value="3.65496122891897"/>
      <inertia ixx="0.0939027722318147" ixy="8.67034465286481E-06" ixz="0.00825983798375924" iyy="0.0906641678816529" iyz="-3.42305751043282E-06" izz="0.133976532477053"/>
    </inertial>
    <visual>
      <origin rpy="0 0 0" xyz="0 0 0"/>
      <geometry>
        <mesh filename="package://artpark/meshes/chassis.STL"/>
      </geometry>
      <material name="">
        <color rgba="0.898039215686275 0.917647058823529 0.929411764705882 1"/>
      </material>
    </visual>
    <collision>
      <origin rpy="0 0 0" xyz="0 0 0"/>
      <geometry>
        <mesh filename="package://artpark/meshes/chassis.STL"/>
      </geometry>
    </collision>
  </link>
  <joint name="base" type="fixed">
    <origin rpy="0 0 0" xyz="0 0 0"/>
    <parent link="base_link"/>
    <child link="chassis"/>
    <axis xyz="0 0 0"/>
  </joint>
  <link name="side_plate1">
    <inertial>
      <origin rpy="0 0 0" xyz="-5.55111512312578E-17 0.0015 -2.77555756156289E-17"/>
      <mass value="0.891200986442893"/>
      <inertia ixx="0.0055991878087458" ixy="-7.04449901036779E-18" ixz="-0.00115377544948716" iyy="0.0187870985074128" iyz="-3.41715046677134E-17" izz="0.0131892475001466"/>
    </inertial>
    <visual>
      <origin rpy="0 0 0" xyz="0 0 0"/>
      <geometry>
        <mesh filename="package://artpark/meshes/side_plate1.STL"/>
      </geometry>
      <material name="">
        <color rgba="0.898039215686275 0.917647058823529 0.929411764705882 1"/>
      </material>
    </visual>
    <collision>
      <origin rpy="0 0 0" xyz="0 0 0"/>
      <geometry>
        <mesh filename="package://artpark/meshes/side_plate1.STL"/>
      </geometry>
    </collision>
  </link>
  <joint name="sp1" type="fixed">
    <origin rpy="0 0 0" xyz="0.29082 -0.213 0.09851"/>
    <parent link="base_link"/>
    <child link="side_plate1"/>
    <axis xyz="0 0 0"/>
  </joint>
  <link name="picker">
    <inertial>
      <origin rpy="0 0 0" xyz="0.00452253303120231 -0.00300695664251519 -0.0314825869268321"/>
      <mass value="1.30544325391666"/>
      <inertia ixx="0.0199932893133936" ixy="1.53560121461935E-05" ixz="0.000231234517093043" iyy="0.00184846628879658" iyz="-0.00010678694913416" izz="0.0184313245740529"/>
    </inertial>
    <visual>
      <origin rpy="0 0 0" xyz="0 0 0"/>
      <geometry>
        <mesh filename="package://artpark/meshes/picker.STL"/>
      </geometry>
      <material name="">
        <color rgba="1 1 1 1"/>
      </material>
    </visual>
    <collision>
      <origin rpy="0 0 0" xyz="0 0 0"/>
      <geometry>
        <mesh filename="package://artpark/meshes/picker.STL"/>
      </geometry>
    </collision>
  </link>
  <joint name="pic" type="continuous">
    <origin rpy="0 0 0" xyz="0.016013 0.21352 -0.027525"/>
    <parent link="side_plate1"/>
    <child link="picker"/>
    <axis xyz="0 1 0"/>
    <transmission name="pic_trans">
      <type>transmission_interface/SimpleTransmission</type>
      <joint name="pic">
        <hardwareInterface>hardware_interface/EffortJointInterface</hardwareInterface>
      </joint>
      <actuator name="pic_motor"/>
      <mechanicalReduction>50</mechanicalReduction>
    </transmission>
  </joint>
  <link name="side_plate2">
    <inertial>
      <origin rpy="0 0 0" xyz="0 -0.00150000000000006 0"/>
      <mass value="0.891200986442893"/>
      <inertia ixx="0.0055991878087458" ixy="-7.04797316894053E-18" ixz="-0.00115377544948716" iyy="0.0187870985074128" iyz="-3.41772949320013E-17" izz="0.0131892475001466"/>
    </inertial>
    <visual>
      <origin rpy="0 0 0" xyz="0 0 0"/>
      <geometry>
        <mesh filename="package://artpark/meshes/side_plate2.STL"/>
      </geometry>
      <material name="">
        <color rgba="0.898039215686275 0.917647058823529 0.929411764705882 1"/>
      </material>
    </visual>
    <collision>
      <origin rpy="0 0 0" xyz="0 0 0"/>
      <geometry>
        <mesh filename="package://artpark/meshes/side_plate2.STL"/>
      </geometry>
    </collision>
  </link>
  <joint name="sp2" type="fixed">
    <origin rpy="0 0 0" xyz="0.29082 0.213 0.09851"/>
    <parent link="base_link"/>
    <child link="side_plate2"/>
    <axis xyz="0 0 0"/>
  </joint>
  <link name="motor1">
    <inertial>
      <origin rpy="0 0 0" xyz="-5.55111512312578E-16 0.080765217008469 -4.71844785465692E-16"/>
      <mass value="1.14513610116382"/>
      <inertia ixx="0.00162507606888743" ixy="9.5001150524092E-18" ixz="6.40137134624859E-21" iyy="0.000258120014856387" iyz="8.39647502242144E-18" izz="0.00162507606888743"/>
    </inertial>
    <visual>
      <origin rpy="0 0 0" xyz="0 0 0"/>
      <geometry>
        <mesh filename="package://artpark/meshes/motor1.STL"/>
      </geometry>
      <material name="">
        <color rgba="0.831372549019608 0.83921568627451 0.831372549019608 1"/>
      </material>
    </visual>
    <collision>
      <origin rpy="0 0 0" xyz="0 0 0"/>
      <geometry>
        <mesh filename="package://artpark/meshes/motor1.STL"/>
      </geometry>
    </collision>
  </link>
  <joint name="m1" type="fixed">
    <origin rpy="0 0 0" xyz="0.12771 -0.176 0.038"/>
    <parent link="base_link"/>
    <child link="motor1"/>
    <axis xyz="0 0 0"/>
  </joint>
  <link name="wheel1">
    <inertial>
      <origin rpy="0 0 0" xyz="7.21644966006352E-16 0.00985771445175607 1.80411241501588E-16"/>
      <mass value="0.349432628407881"/>
      <inertia ixx="0.000526136247776357" ixy="-4.12571912424266E-18" ixz="3.79678739425313E-17" iyy="0.00101551394512694" iyz="-3.1676126616374E-18" izz="0.000526136247776314"/>
    </inertial>
    <visual>
      <origin rpy="0 0 0" xyz="0 0 0"/>
      <geometry>
        <mesh filename="package://artpark/meshes/wheel1.STL"/>
      </geometry>
      <material name="">
        <color rgba="1 1 1 1"/>
      </material>
    </visual>
    <collision>
      <origin rpy="0 0 0" xyz="0 0 0"/>
      <geometry>
        <mesh filename="package://artpark/meshes/wheel1.STL"/>
      </geometry>
    </collision>
  </link>
  <joint name="w1" type="continuous">
    <origin rpy="0 0 0" xyz="0 -0.061701 0"/>
    <parent link="motor1"/>
    <child link="wheel1"/>
    <axis xyz="0 1 0"/>
    <transmission name="w1_trans">
      <type>transmission_interface/SimpleTransmission</type>
      <joint name="w1">
        <hardwareInterface>hardware_interface/EffortJointInterface</hardwareInterface>
      </joint>
      <actuator name="w1_motor"/>
    </transmission>
  </joint>
  <link name="motor2">
    <inertial>
      <origin rpy="0 0 0" xyz="-5.55111512312578E-17 -0.0807652170084691 4.85722573273506E-16"/>
      <mass value="1.14513610116382"/>
      <inertia ixx="0.00162507606888743" ixy="-1.00101410880249E-20" ixz="-7.5078941239734E-21" iyy="0.000258120014856386" iyz="8.14969822443002E-18" izz="0.00162507606888743"/>
    </inertial>
    <visual>
      <origin rpy="0 0 0" xyz="0 0 0"/>
      <geometry>
        <mesh filename="package://artpark/meshes/motor2.STL"/>
      </geometry>
      <material name="">
        <color rgba="0.831372549019608 0.83921568627451 0.831372549019608 1"/>
      </material>
    </visual>
    <collision>
      <origin rpy="0 0 0" xyz="0 0 0"/>
      <geometry>
        <mesh filename="package://artpark/meshes/motor2.STL"/>
      </geometry>
    </collision>
  </link>
  <joint name="m2" type="fixed">
    <origin rpy="0 0 0" xyz="0.12771 0.176 0.038"/>
    <parent link="base_link"/>
    <child link="motor2"/>
    <axis xyz="0 0 0"/>
  </joint>
  <link name="wheel2">
    <inertial>
      <origin rpy="0 0 0" xyz="-8.32667268468867E-16 -0.00985771445175598 1.38777878078145E-17"/>
      <mass value="0.349432628407874"/>
      <inertia ixx="0.000526136247776362" ixy="-7.98207927791519E-19" ixz="-2.25842144795148E-17" iyy="0.00101551394512691" iyz="-2.91448262559538E-18" izz="0.000526136247776281"/>
    </inertial>
    <visual>
      <origin rpy="0 0 0" xyz="0 0 0"/>
      <geometry>
        <mesh filename="package://artpark/meshes/wheel2.STL"/>
      </geometry>
      <material name="">
        <color rgba="1 1 1 1"/>
      </material>
    </visual>
    <collision>
      <origin rpy="0 0 0" xyz="0 0 0"/>
      <geometry>
        <mesh filename="package://artpark/meshes/wheel2.STL"/>
      </geometry>
    </collision>
  </link>
  <joint name="w2" type="continuous">
    <origin rpy="0 0 0" xyz="0 0.061701 0"/>
    <parent link="motor2"/>
    <child link="wheel2"/>
    <axis xyz="0 1 0"/>
    <transmission name="w2_trans">
      <type>transmission_interface/SimpleTransmission</type>
      <joint name="w2">
        <hardwareInterface>hardware_interface/EffortJointInterface</hardwareInterface>
      </joint>
      <actuator name="w2_motor"/>
    </transmission>
  </joint>
  <link name="rplidar">
    <inertial>
      <origin rpy="0 0 0" xyz="-0.00283140368793464 0.000495101457548164 0.00443830911249521"/>
      <mass value="0.142993661893579"/>
      <inertia ixx="4.62765933116063E-05" ixy="-8.53487841648092E-07" ixz="3.62171002036755E-06" iyy="7.34741694839761E-05" iyz="-2.04305204081226E-07" izz="0.000107959645241711"/>
    </inertial>
    <visual>
      <origin rpy="0 0 0" xyz="0 0 0"/>
      <geometry>
        <mesh filename="package://artpark/meshes/rplidar.STL"/>
      </geometry>
      <material name="">
        <color rgba="0.792156862745098 0.819607843137255 0.933333333333333 1"/>
      </material>
    </visual>
    <collision>
      <origin rpy="0 0 0" xyz="0 0 0"/>
      <geometry>
        <mesh filename="package://artpark/meshes/rplidar.STL"/>
      </geometry>
    </collision>
  </link>
  <!-- camera body, with origin at bottom screw mount -->
  <joint name="d435_joint" type="fixed">
    <origin rpy="0 0 0" xyz="0.04 0.0 -0.08"/>
    <parent link="rplidar"/>
    <child link="d435_bottom_screw_frame"/>
  </joint>
  <link name="d435_bottom_screw_frame"/>
  <joint name="d435_link_joint" type="fixed">
    <origin rpy="0 0 0" xyz="0 0.0175 0.0125"/>
    <parent link="d435_bottom_screw_frame"/>
    <child link="d435_link"/>
  </joint>
  <link name="d435_link">
    <visual>
      <origin rpy="1.5707963267948966 0 1.5707963267948966" xyz="0.0149 -0.0175 0"/>
      <geometry>
        <mesh filename="package://realsense_ros_gazebo/meshes/realsense_d435.stl"/>
      </geometry>
    </visual>
    <collision>
      <origin rpy="0 0 0" xyz="0 -0.0175 0"/>
      <geometry>
        <box size="0.02505 0.09 0.025"/>
      </geometry>
    </collision>
    <inertial>
      <mass value="0.564"/>
      <origin rpy="0 0 0" xyz="0 -0.0175 0"/>
      <inertia ixx="0.000410075" ixy="0" ixz="0" iyy="5.8867617499999996e-05" iyz="0" izz="5.8867617499999996e-05"/>
    </inertial>
  </link>
  <!-- camera depth joints and links -->
  <joint name="d435_depth_joint" type="fixed">
    <origin rpy="0 0 0" xyz="0 0 0"/>
    <parent link="d435_link"/>
    <child link="d435_depth_frame"/>
  </joint>
  <link name="d435_depth_frame"/>
  <joint name="d435_depth_optical_joint" type="fixed">
    <origin rpy="-1.5707963267948966 0 -1.5707963267948966" xyz="0 0 0"/>
    <parent link="d435_depth_frame"/>
    <child link="d435_depth_optical_frame"/>
  </joint>
  <link name="d435_depth_optical_frame"/>
  <!-- camera left IR joints and links -->
  <joint name="d435_left_ir_joint" type="fixed">
    <origin rpy="0 0 0" xyz="0 0.0 0"/>
    <parent link="d435_depth_frame"/>
    <child link="d435_left_ir_frame"/>
  </joint>
  <link name="d435_left_ir_frame"/>
  <joint name="d435_left_ir_optical_joint" type="fixed">
    <origin rpy="-1.5707963267948966 0 -1.5707963267948966" xyz="0 0 0"/>
    <parent link="d435_left_ir_frame"/>
    <child link="d435_left_ir_optical_frame"/>
  </joint>
  <link name="d435_left_ir_optical_frame"/>
  <!-- camera right IR joints and links -->
  <joint name="d435_right_ir_joint" type="fixed">
    <origin rpy="0 0 0" xyz="0 -0.05 0"/>
    <parent link="d435_depth_frame"/>
    <child link="d435_right_ir_frame"/>
  </joint>
  <link name="d435_right_ir_frame"/>
  <joint name="d435_right_ir_optical_joint" type="fixed">
    <origin rpy="-1.5707963267948966 0 -1.5707963267948966" xyz="0 0 0"/>
    <parent link="d435_right_ir_frame"/>
    <child link="d435_right_ir_optical_frame"/>
  </joint>
  <link name="d435_right_ir_optical_frame"/>
  <!-- camera color joints and links -->
  <joint name="d435_color_joint" type="fixed">
    <origin rpy="0 0 0" xyz="0 0.015 0"/>
    <parent link="d435_depth_frame"/>
    <child link="d435_color_frame"/>
  </joint>
  <link name="d435_color_frame"/>
  <joint name="d435_color_optical_joint" type="fixed">
    <origin rpy="-1.5707963267948966 0 -1.5707963267948966" xyz="0 0 0"/>
    <parent link="d435_color_frame"/>
    <child link="d435_color_optical_frame"/>
  </joint>
  <link name="d435_color_optical_frame"/>
  <!-- gazebo plugin -->
  <gazebo reference="d435_link">
    <self_collide>0</self_collide>
    <enable_wind>0</enable_wind>
    <kinematic>0</kinematic>
    <gravity>1</gravity>
    <mu2>1</mu2>
    <fdir1>0 0 0</fdir1>
    <kp>1e+13</kp>
    <kd>1</kd>
    <sensor name="d435_color" type="camera">
      <camera name="d435">
        <horizontal_fov>1.2112585008840648</horizontal_fov>
        <image>
          <width>640</width>
          <height>480</height>
          <format>RGB_INT8</format>
        </image>
        <clip>
          <near>0.1</near>
          <far>100</far>
        </clip>
        <noise>
          <type>gaussian</type>
          <mean>0.0</mean>
          <stddev>0.007</stddev>
        </noise>
      </camera>
      <always_on>1</always_on>
      <update_rate>30</update_rate>
      <visualize>1</visualize>
    </sensor>
    <sensor name="d435_ired1" type="camera">
      <camera name="d435">
        <horizontal_fov>1.4870205226991688</horizontal_fov>
        <image>
          <width>640</width>
          <height>480</height>
          <format>L_INT8</format>
        </image>
        <clip>
          <near>0.1</near>
          <far>100</far>
        </clip>
        <noise>
          <type>gaussian</type>
          <mean>0.0</mean>
          <stddev>0.05</stddev>
        </noise>
      </camera>
      <always_on>1</always_on>
      <update_rate>90</update_rate>
      <visualize>0</visualize>
    </sensor>
    <sensor name="d435_ired2" type="camera">
      <camera name="d435">
        <horizontal_fov>1.4870205226991688</horizontal_fov>
        <image>
          <width>640</width>
          <height>480</height>
          <format>L_INT8</format>
        </image>
        <clip>
          <near>0.1</near>
          <far>100</far>
        </clip>
        <noise>
          <type>gaussian</type>
          <mean>0.0</mean>
          <stddev>0.05</stddev>
        </noise>
      </camera>
      <always_on>1</always_on>
      <update_rate>90</update_rate>
      <visualize>0</visualize>
    </sensor>
    <sensor name="d435_depth" type="depth">
      <camera name="d435">
        <horizontal_fov>1.4870205226991688</horizontal_fov>
        <image>
          <width>640</width>
          <height>480</height>
        </image>
        <clip>
          <near>0.1</near>
          <far>100</far>
        </clip>
        <noise>
          <type>gaussian</type>
          <mean>0.0</mean>
          <stddev>0.100</stddev>
        </noise>
      </camera>
      <always_on>1</always_on>
      <update_rate>90</update_rate>
      <visualize>0</visualize>
    </sensor>
  </gazebo>
  <gazebo>
    <plugin filename="librealsense_gazebo_plugin.so" name="d435">
      <prefix>d435_</prefix>
      <depthUpdateRate>10</depthUpdateRate>
      <colorUpdateRate>10</colorUpdateRate>
      <infraredUpdateRate>10</infraredUpdateRate>
      <depthTopicName>depth/image_raw</depthTopicName>
      <depthCameraInfoTopicName>depth/camera_info</depthCameraInfoTopicName>
      <colorTopicName>color/image_raw</colorTopicName>
      <colorCameraInfoTopicName>color/camera_info</colorCameraInfoTopicName>
      <infrared1TopicName>infra1/image_raw</infrared1TopicName>
      <infrared1CameraInfoTopicName>infra1/camera_info</infrared1CameraInfoTopicName>
      <infrared2TopicName>infra2/image_raw</infrared2TopicName>
      <infrared2CameraInfoTopicName>infra2/camera_info</infrared2CameraInfoTopicName>
      <colorOpticalframeName>d435_color_optical_frame</colorOpticalframeName>
      <depthOpticalframeName>d435_depth_optical_frame</depthOpticalframeName>
      <infrared1OpticalframeName>d435_infrared1_optical_frame</infrared1OpticalframeName>
      <infrared2OpticalframeName>d435_infrared2_optical_frame</infrared2OpticalframeName>
      <rangeMinDepth>0.2</rangeMinDepth>
      <rangeMaxDepth>10.0</rangeMaxDepth>
      <pointCloud>false</pointCloud>
      <pointCloudTopicName>depth/color/points</pointCloudTopicName>
      <pointCloudCutoff>0.25</pointCloudCutoff>
      <pointCloudCutoffMax>9.0</pointCloudCutoffMax>
    </plugin>
  </gazebo>
  <joint name="rpl1" type="fixed">
    <origin rpy="0 0 0" xyz="-0.040672 0 0.5406"/>
    <parent link="base_link"/>
    <child link="rplidar"/>
    <axis xyz="0 0 0"/>
  </joint>
  <link name="castor">
    <inertial>
      <origin rpy="0 0 0" xyz="0 0 0"/>
      <mass value="0.001"/>
      <inertia ixx="0" ixy="0" ixz="0" iyy="0" iyz="0" izz="0"/>
    </inertial>
    <visual>
      <origin rpy="0 0 0" xyz="0 0 0"/>
      <geometry>
        <mesh filename="package://artpark/meshes/castor.STL"/>
      </geometry>
      <material name="">
        <color rgba="5 1 1 1"/>
      </material>
    </visual>
    <collision>
      <origin rpy="0 0 0" xyz="0 0 0"/>
      <geometry>
        <mesh filename="package://artpark/meshes/castor.STL"/>
      </geometry>
    </collision>
  </link>
  <joint name="c1" type="fixed">
    <origin rpy="0 0 0" xyz="-0.21229 0 -0.018"/>
    <parent link="base_link"/>
    <child link="castor"/>
    <axis xyz="0 0 0"/>
  </joint>
  <link name="castor_ball">
    <inertial>
      <origin rpy="0 0 0" xyz="-1.3878E-17 0 0"/>
      <mass value="0.00065958"/>
      <inertia ixx="7.6934E-09" ixy="-1.5071E-25" ixz="6.9793E-26" iyy="7.6934E-09" iyz="-2.7917E-26" izz="7.6934E-09"/>
    </inertial>
    <visual>
      <origin rpy="0 0 0" xyz="0 0 0"/>
      <geometry>
        <mesh filename="package://artpark/meshes/castor_ball.STL"/>
      </geometry>
      <material name="">
        <color rgba="0.69804 0.69804 0.69804 1"/>
      </material>
    </visual>
    <collision>
      <origin rpy="0 0 0" xyz="0 0 0"/>
      <geometry>
        <mesh filename="package://artpark/meshes/castor_ball.STL"/>
      </geometry>
    </collision>
  </link>
  <joint name="b1" type="continuous">
    <origin rpy="0 0 0" xyz="0 0 -0.011429"/>
    <parent link="castor"/>
    <child link="castor_ball"/>
    <axis xyz="1 1 1"/>
  </joint>
</robot>

